Workbook
Name Alternative_2: [1]Umsätze!#REF!
Name Alternative_2: [1]Umsätze!#REF!
Name Alternative_2: [2]Umsätze!#REF!
Name Alternative_2: [3]Umsätze!#REF!
Name Alternative_3: [1]Umsätze!#REF!
Name Alternative_3: [1]Umsätze!#REF!
Name Alternative_3: [2]Umsätze!#REF!
Name Alternative_3: [3]Umsätze!#REF!
Name Alternative_4: [1]Umsätze!#REF!
Name Alternative_4: [1]Umsätze!#REF!
Name Alternative_4: [2]Umsätze!#REF!
Name Alternative_4: [3]Umsätze!#REF!
Name Kosten: '[4]2014'!$C$61
Name Kosten: '[5]2014'!$C$61
Name Kosten: '[6]2012'!$C$62
Name Kosten: '[7]2012'!$C$62
Name Kosten: '[8]2012'!$C$62
Name Kosten: '[9]2012'!$C$62
Name Materialkosten: #REF!
Name Materialkosten: #REF!
Name Materialkosten: #REF!
Name Materialkosten_Rechner__Jahresplanung_ohne_monatsgenaue_Verteilung: #REF!
Name Materialkosten_Rechner__Jahresplanung_ohne_monatsgenaue_Verteilung: #REF!
Name Materialkosten_Rechner__Jahresplanung_ohne_monatsgenaue_Verteilung: #REF!
Name MoUm: '[4]2014'!$C$60
Name MoUm: '[5]2014'!$C$60
Name MoUm: '[6]2012'!$C$61
Name MoUm: '[7]2012'!$C$61
Name MoUm: '[8]2012'!$C$61
Name MoUm: '[9]2012'!$C$61
Name UmRe: '[4]2014'!$C$59
Name UmRe: '[5]2014'!$C$59
Name UmRe: '[6]2012'!$C$60
Name UmRe: '[7]2012'!$C$60
Name UmRe: '[8]2012'!$C$60
Name UmRe: '[9]2012'!$C$60
Name Var1_Handw_DL: '[4]2013'!$I$53
Name Var1_Handw_DL: '[7]2011'!$I$50
Name Var1_Handw_DL: '[10]2013'!$I$53
Name Var1_Handw_DL: '[5]2013'!$I$53
Name Var2_Han_Gastro: '[4]2013'!$I$54
Name Var2_Han_Gastro: '[7]2011'!$I$51
Name Var2_Han_Gastro: '[10]2013'!$I$54
Name Var2_Han_Gastro: '[5]2013'!$I$54
Name WE: '[4]2014'!$C$62
Name WE: '[5]2014'!$C$62
Name WE: '[6]2012'!$C$63
Name WE: '[7]2012'!$C$63
Name WE: '[8]2012'!$C$63
Name WE: '[9]2012'!$C$63
Name WL_BP_De: Deckblatt!#REF!
Name WL_BP_Fm: Deckblatt!#REF!
Name WL_BP_Mm: Deckblatt!$B$16
Name WL_BP_Re: Deckblatt!#REF!
Name WL_BP_To: Deckblatt!#REF!

Sheet Deckblatt
Y1: Januar | Z1: Februar | AA1: März | AB1: April | AC1: Mai | AD1: Juni | AE1: Juli | AF1: August | AG1: September | AH1: Oktober | AI1: November | AJ1: Dezember
B2: BUSINESSPLAN ZAHLENTEIL | Y2: Februar | Z2: März | AA2: April | AB2: Mai | AC2: Juni | AD2: Juli | AE2: August | AF2: September | AG2: Oktober | AH2: November | AI2: Dezember | AJ2: Januar
Y3: März | Z3: April | AA3: Mai | AB3: Juni | AC3: Juli | AD3: August | AE3: September | AF3: Oktober | AG3: November | AH3: Dezember | AI3: Januar | AJ3: Februar
B4: Firmenname: | C4: Muster GbR | Y4: April | Z4: Mai | AA4: Juni | AB4: Juli | AC4: August | AD4: September | AE4: Oktober | AF4: November | AG4: Dezember | AH4: Januar | AI4: Februar | AJ4: März
B5: GründerIn: | C5: Max Mustermann | G5: Siehe Unten >>>>>>>>> | Y5: Mai | Z5: Juni | AA5: Juli | AB5: August | AC5: September | AD5: Oktober | AE5: November | AF5: Dezember | AG5: Januar | AH5: Februar | AI5: März | AJ5: April
B6: Stand: | C6: =TODAY() -> 45978 | Y6: Juni | Z6: Juli | AA6: August | AB6: September | AC6: Oktober | AD6: November | AE6: Dezember | AF6: Januar | AG6: Februar | AH6: März | AI6: April | AJ6: Mai
B7: geplantes Jahr der Gründung : | C7: 2025 | Y7: Juli | Z7: August | AA7: September | AB7: Oktober | AC7: November | AD7: Dezember | AE7: Januar | AF7: Februar | AG7: März | AH7: April | AI7: Mai | AJ7: Juni
B8: geplanter Monat der Gründung: | C8: Jan. | Y8: August | Z8: September | AA8: Oktober | AB8: November | AC8: Dezember | AD8: Januar | AE8: Februar | AF8: März | AG8: April | AH8: Mai | AI8: Juni | AJ8: Juli
B9: Umsatzsteuersatz: | C9: 0.19 | Y9: September | Z9: Oktober | AA9: November | AB9: Dezember | AC9: Januar | AD9: Februar | AE9: März | AF9: April | AG9: Mai | AH9: Juni | AI9: Juli | AJ9: August
Y10: Oktober | Z10: November | AA10: Dezember | AB10: Januar | AC10: Februar | AD10: März | AE10: April | AF10: Mai | AG10: Juni | AH10: Juli | AI10: August | AJ10: September
Y11: November | Z11: Dezember | AA11: Januar | AB11: Februar | AC11: März | AD11: April | AE11: Mai | AF11: Juni | AG11: Juli | AH11: August | AI11: September | AJ11: Oktober
Y12: Dezember | Z12: Januar | AA12: Februar | AB12: März | AC12: April | AD12: Mai | AE12: Juni | AF12: Juli | AG12: August | AH12: September | AI12: Oktober | AJ12: November
B15: INHALT
B18: Deckblatt | C18: Seite 0
B19: Gewinn- u. Verlustrechnung 1. Geschäftsjahr | C19: Seite 1
B20: Gewinn- u. Verlustrechnung 2. Geschäftsjahr | C20: Seite 2
B21: Gewinn- u. Verlustrechnung 3. Geschäftsjahr | C21: Seite 3 | E21: Businessplan relevant
B22: Umsatzplanung 1.-3. Geschäftsjahr | C22: Seite 4
B23: Liquiditätsrechnung 1.-3. Jahr | C23: Seite 5
B24: Privatentnahmen | C24: Seite 6
B25: Finanzen_AfA_Investitionen | C25: Seite 7
B26: ArbStd_MA | C26: Seite 8
B27: Einzelkalkulation Gastronomie | C27: Seite 9
B28: Einzelkalkulation Handwerk | C28: Seite 10
B29: Einzelkalkulation Handel | C29: Seite 11 | E29: Kalkulationsteil
B30: Einzelkalkulation DL | C30: Seite 12
B31: Kalkul.Einzelpreise | C31: Seite 13
B32: Zusammenfassung | C32: Seite 14
G99: Jan. | H99: Febr. | I99: März | J99: April | K99: Mai | L99: Juni | M99: Juli | N99: Aug. | O99: Sept. | P99: Okt. | Q99: Nov. | R99: Dez.
G100: Febr. | H100: März | I100: April | J100: Mai | K100: Juni | L100: Juli | M100: Aug. | N100: Sept. | O100: Okt. | P100: Nov. | Q100: Dez. | R100: Jan.
G101: März | H101: April | I101: Mai | J101: Juni | K101: Juli | L101: Aug. | M101: Sept. | N101: Okt. | O101: Nov. | P101: Dez. | Q101: Jan. | R101: Febr.
G102: April | H102: Mai | I102: Juni | J102: Juli | K102: Aug. | L102: Sept. | M102: Okt. | N102: Nov. | O102: Dez. | P102: Jan. | Q102: Febr. | R102: März
G103: Mai | H103: Juni | I103: Juli | J103: Aug. | K103: Sept. | L103: Okt. | M103: Nov. | N103: Dez. | O103: Jan. | P103: Febr. | Q103: März | R103: April
G104: Juni | H104: Juli | I104: Aug. | J104: Sept. | K104: Okt. | L104: Nov. | M104: Dez. | N104: Jan. | O104: Febr. | P104: März | Q104: April | R104: Mai
G105: Juli | H105: Aug. | I105: Sept. | J105: Okt. | K105: Nov. | L105: Dez. | M105: Jan. | N105: Febr. | O105: März | P105: April | Q105: Mai | R105: Juni
G106: Aug. | H106: Sept. | I106: Okt. | J106: Nov. | K106: Dez. | L106: Jan. | M106: Febr. | N106: März | O106: April | P106: Mai | Q106: Juni | R106: Juli
G107: Sept. | H107: Okt. | I107: Nov. | J107: Dez. | K107: Jan. | L107: Febr. | M107: März | N107: April | O107: Mai | P107: Juni | Q107: Juli | R107: Aug.
G108: Okt. | H108: Nov. | I108: Dez. | J108: Jan. | K108: Febr. | L108: März | M108: April | N108: Mai | O108: Juni | P108: Juli | Q108: Aug. | R108: Sept.
G109: Nov. | H109: Dez. | I109: Jan. | J109: Febr. | K109: März | L109: April | M109: Mai | N109: Juni | O109: Juli | P109: Aug. | Q109: Sept. | R109: Okt.
G110: Dez. | H110: Jan. | I110: Febr. | J110: März | K110: April | L110: Mai | M110: Juni | N110: Juli | O110: Aug. | P110: Sept. | Q110: Okt. | R110: Nov.

Sheet Selbstverständnis
A1: Memo | D1: =TODAY() -> 45978 | L1: Es ist nicht genug zu wissen, man muss es auch anwenden! Es ist nicht genug zu wollen, man muß es auch tun! Johann Wolfgang von Goethe
A2: An: Alle Benutzer der Tabelle
A3: Von: Rüdiger ADAMY
A6: Betreff: | B6: Finanzplanung, wie ich sie verstehe, heißt:
B8: Sinn und Zweck der Planungen ist es, Ihnen einen möglichst genauen und umfassenden Überblick über die künftige Entwicklung der Unternehmung, über Kosten, Erlöse und Gewinne zu geben.
A9: ► 1
A12: ► 2 | B12: Die vorliegende Planungstabelle, (auch Umsatz- und Ertragsvorschau genannt) ist Teil der Gesamtplanung eines Unternehmens, sie besteht aus 2 Gruppen von Datenblättern. Zum einen: Finanzplanung; darunter verstehen man die Kostenplanung, die Umsatzplanung, die Liquiditätsplanung und die Kapitalbedarfsplanung (für die notwendigen Investitionen)
A16: ► 3 | B16: Zum zweiten erhalten Sie eine wichtige Basis für die Gesamtkalkulation, danach für die Einzelkalkulation von Preisen und Dienstleistungen (in verschiedener Art für Handwerk, Handel, Dienstleistung und Gastronomie.
A20: ► 4 | B20: Sie beginnen mit der Kostenplanung, danach folgt die Umsatzplanung ( ausgehend von Einzelleistunen je Tag, Woche oder Monat und soweit nötig mit dem dazu gehörenden Zeitbedarf). Zum Schluß sollten Sie die Umsatzplanung mit einem Marketing+Aktivitätenplan unterlegen, im dem Sie beschreiben, wie Sie zu Kunden und Abschlüssen kommen. Alle hieraus gewonnenen Daten bilden die Grundlage zur Erstellung der Liquidtätsrechnung .
A26: ► 5 | B26: Zum Abschluß dieser Planungsschritte sind Sie in der Lage, ausgehend von Ihren eigenen Zahlen eine Kalkulation Ihrer Preise zu machen. Dann können Sie prüfen, wie Ihre Situation am Markt ist. Die Planungstabelle ist ein Werkzeug mit dessen Hilfe Sie zuverlässig erkennen können, ob Sie rentabel arbeiten, wo Spielräume im täglichen Preiskampf sind, und wo Ihre Stärken und Schwächen liegen!

Sheet Richtig Planen

Sheet Vorblatt Auftragsakquise 
B3: Tipps und Hinweise zur Kunden/Auftragsakquisition
B7: Umsatzplanung bei der Gründung ist der wohl schwierigste und anspruchsvollste Teil der Finanzplanung, weil keine Vergleichswerte noch Erfahrungen vorhanden sind! Trotzdem ist es notwendig dies zu tun, und dabei kaufmännische Vorsicht walten zu lassen.
A8: ►1
A12: ►2 | B12: Eine möglichst zutreffende Planung wird durch folgende Fakten untermauert: 1) welche Daten und Erkenntnisse hat die Markterkundung gebracht? 2) welche Akquisitionswege habe ich für mein Gewerk als richtig erkannt und festgelegt? 3) Welche Ansprache mache ich bei Kunden und Nichtkunden?
B17: Das beigefügte Rechentool geht davon aus, daß Ansprachen regelmäßig in gewisser Anzahl gemacht werden; und daß davon nur Teilmengen für weiterführende Akquisition und für Auftragserteilung in Frage kommen
A18: ►3
B22: Sie erhalten bei Nutzung und Einstellung der Datei auf Ihre Werte wichtige Hindweise zur Anzahl der Ansprachen (neutral ausgedrückt, also Telefonate, Mails, Briefe usw) und zum Zeitbedarf!
A23: ►4
B27: Alle Maßnahmen und Aktionen sollten dann in einem Aktivitäten- und Marketingplan zusammengefasst werden und in monatlichen Teilen abgearbeitet werden!
A29: ►5

Sheet Fachbegriffe
B1: Erläuterungen von Fachbegriffen in den Tabellenblättern
B2: Ertragsvorschau
C4: Stundenverkaufssatz | J4: Mindeststundensatz:
B6: `+1) | C6: PRIVATE KOSTEN | I6: `+1) | J6: PRIVATE KOSTEN
B7: +2) | C7: GEWERBLICHE KOSTEN + WARENEINSATZ | I7: +2) | J7: GEWERBLICHE KOSTEN + WARENEINSATZ
B8: `+3) | C8: 3% RISIKOZUSCHLAG UNTERNEHM. TÄTIGKEIT (SOZIALE SICHERUNG)
B9: +4) | C9: 10% EIGENKAPITALVERZINSUNG
B10: `+5) | C10: KALKULATORISCHE STEUERN | I10: `+5) | J10: KALKULATORISCHE STEUERN
B11: +6) | C11: 5% REINGEWINNANSPRUCH
B12: `+7) | C12: 2% GARANTIE UND GEWÄHRLEISTUNG
B13: +8) | C13: RISIKOZUSCHLAG FÜR SAISON-/SONDERVERKÄUFE / NACHLÄSSE
B14: `+9) | C14: RISIKOZUSCHLAG FÜR UMSATZLOSE ZEIT
C15: dividiert durch Prod. Stunden | J15: dividiert durch Prod. Stunden
C16: dividiert durch Anzahl Prod. MA | J16: dividiert durch Prod. MA
B19: Liquiditätsplan
C21: Vorsteuer:
C23: Material/Waren
B24: + | C24: Anlageninvestitionen
B25: + | C25: Betriebsausgaben
B26: - | C26: Kfz Steuer
B27: - | C27: Versicherungen/Beiträge
B28: - | C28: Zinsen
B29: - | C29: Personalkosten
C30: multipliziert mit 19%
B32: Zusammenfassung
C34: realisierter Stundensatz:
C36: Summe Aufwendungen
B37: - | C37: Material
B38: + | C38: Abschreibungen
B39: + | C39: Gewinn/Verlust
C40: dividiert durch Prod. Stunden
C41: dividiert durch Anzahl Prod. MA
C43: Nettocashflow:
C45: Gewinn/Verlust
B46: + | C46: Abschreibungen
B47: - | C47: Kalk. Steuern
B48: - | C48: Unternehmerlohn

Sheet AnalyseFragen
A1: =Deckblatt!C5 -> Max Mustermann
A3: Umsatz
A7: Liquidität
A13: Wareneinsatz
A17: Kosten o.WE
A21: Prod.Std +MA
A25: Privatentnahme
A29: Gewinn
A33: Kalkulation
A37: Controlling

Sheet Abfolge der Einzelblätter

Sheet ZusammenführErgebn
B1: ZUSAMMENFÜHRUNG VON ERGEBNISZAHLEN
B3: WICHTIGE ERGEBNISZAHLEN | C3: 2025 | D3: 2026 | E3: 2027
B5: Umsätze/Erlöse | C5: ='Ertragsv. 2025'!O3 -> 0 | D5: ='Ertragsv. 2026'!O3 -> 0 | E5: ='Ertragsv. 2027'!O3 -> 0
B7: Wareneinkauf : Umsatz | C7: ='Ertragsv. 2025'!P4/100 -> #DIV/0! | D7: ='Ertragsv. 2026'!P4% -> #DIV/0! | E7: ='Ertragsv. 2027'!P4/100 -> #DIV/0!
B8: Mindestumsatz : Umsatz | C8: ='Ertragsv. 2025'!O3/('Ertragsv. 2025'!M38*12) -> #DIV/0! | D8: ='Ertragsv. 2026'!O3/('Ertragsv. 2026'!M37*12) -> #DIV/0! | E8: ='Ertragsv. 2027'!O3/('Ertragsv. 2027'!M37*12) -> #DIV/0!
B9: Gewinn : Umsatz | C9: ='Ertragsv. 2025'!P23/100 -> #DIV/0! | D9: ='Ertragsv. 2026'!P23/100 -> #DIV/0! | E9: ='Ertragsv. 2027'!P23/100 -> #DIV/0!
B10: Kosten (o. WE) : Umsatz | C10: =('Ertragsv. 2025'!O20-'Ertragsv. 2025'!O4)/'Ertragsv. 2025'!O3 -> #DIV/0! | D10: =('Ertragsv. 2026'!O20-'Ertragsv. 2026'!O4)/'Ertragsv. 2026'!O3 -> #DIV/0! | E10: =('Ertragsv. 2027'!O20-'Ertragsv. 2027'!O4)/'Ertragsv. 2027'!O3 -> #DIV/0!
B12: Durchschn. realisierte Stundensätze | C12: =('Ertragsv. 2025'!O20-'Ertragsv. 2025'!O4+'Ertragsv. 2025'!O22+'Ertragsv. 2025'!O23)/12/'Ertragsv. 2025'!L41/ArbStd_MA!F49 -> 0 | D12: =('Ertragsv. 2026'!O20-'Ertragsv. 2026'!O4+'Ertragsv. 2026'!O22+'Ertragsv. 2026'!O23)/12/'Ertragsv. 2026'!L40/ArbStd_MA!G49 -> 0 | E12: =('Ertragsv. 2027'!O20-'Ertragsv. 2027'!O4+'Ertragsv. 2027'!O22+'Ertragsv. 2027'!O23)/12/'Ertragsv. 2027'!L40/ArbStd_MA!H49 -> 0
B13: Durchschn. notwendige Stundensätze | C13: ='Ertragsv. 2025'!M41 -> 0 | D13: ='Ertragsv. 2026'!M40 -> 0 | E13: ='Ertragsv. 2027'!M40 -> 0
B15: Durchschn.Realisierte Rohaufschläge in % | C15: =IF(Einzelkalk_Handel!D5>0,Einzelkalk_Handel!D5) -> #DIV/0! | D15: =Einzelkalk_Handel!G5 -> #DIV/0! | E15: =Einzelkalk_Handel!J5 -> #DIV/0!
B16: Notwendige Rohaufschläge in % | C16: =Einzelkalk_Handel!D6 -> #DIV/0! | D16: =Einzelkalk_Handel!G6 -> #DIV/0! | E16: =Einzelkalk_Handel!J6 -> #DIV/0!
B18: Gewinn vor Steuern | C18: ='Ertragsv. 2025'!O23 -> 0 | D18: ='Ertragsv. 2026'!O23 -> 0 | E18: ='Ertragsv. 2027'!O23 -> 0
B20: Gewinn nach Steuern | C20: ='Ertragsv. 2025'!O26 -> 0 | D20: ='Ertragsv. 2026'!O26 -> 0 | E20: ='Ertragsv. 2027'!O26 -> 0
B22: Entnahmen d. Unternehmerlohn | C22: ='Ertragsv. 2025'!O27 -> 0 | D22: ='Ertragsv. 2026'!O27 -> 0 | E22: ='Ertragsv. 2027'!O27 -> 0
B24: Ergebnis nach Unternehmerlohn | C24: =C20-C22 -> 0 | D24: =D20-D22 -> 0 | E24: =E20-E22 -> 0
B26: Nettocashflow | C26: ='Ertragsv. 2025'!O23+'Ertragsv. 2025'!O22-'Ertragsv. 2025'!O25-'Ertragsv. 2025'!O27 -> 0 | D26: ='Ertragsv. 2026'!O23+'Ertragsv. 2026'!O22-'Ertragsv. 2026'!O25-'Ertragsv. 2026'!O27 -> 0 | E26: ='Ertragsv. 2027'!O23+'Ertragsv. 2027'!O22-'Ertragsv. 2027'!O25-'Ertragsv. 2027'!O27 -> 0
B28: Bereits für Tilgung verplante Beträge | C28: =Finanz_AfA_Investitionen!$G$38*12 -> 0 | D28: =Finanz_AfA_Investitionen!$G$38*12 -> 0 | E28: =Finanz_AfA_Investitionen!$G$38*12 -> 0
B30: Noch verfügbare Finanzmittel | C30: =C26-C28 -> 0 | D30: =D26-D28 -> 0 | E30: =E26-E28 -> 0
B34: Realisierte Stundensätze im Jahresverlauf
B35: Aus Vorschau
B36: Januar
B37: Februar
B38: März
B39: April
B40: Mai
B41: Juni
B42: Juli
B43: August
B44: September
B45: Oktober
... B62: Dezember

Sheet Privatentnahmen
O1: Hinweise und Plausibilitäten für Darlehensprogramm Microstarter der N-Bank
B2: PRIVATENTNAHME | D2: Bei Kostensprüngen in Folgejahren sollte ein Eingriff in die jeweiligen Formeln erfolgen . Fragen Sie Ihren Berater/Dozenten! | U2: Statistische Durchschnittsrechnung 2013
C4: PRIVATENTNAHME | D4: =ZusammenführErgebn!C3 -> 2025 | F4: =ZusammenführErgebn!D3 -> 2026 | H4: =ZusammenführErgebn!E3 -> 2027 | J4: 4. Jahr | M4: ERLÄUTERUNGEN | V4: =ZusammenführErgebn!U3 -> 0
E5: 12 | F5: Teuerung: | G5: 0.02 | H5: Teuerung: | I5: 0.03 | J5: Teuerung: | K5: 0.05 | N5: Info | W5: 12 | X5: %
D6: MONAT | E6: JAHR | F6: MONAT | G6: JAHR | H6: MONAT | I6: JAHR | J6: Monat | K6: Jahr | N6: MiStart | V6: MONAT | W6: JAHR
C7: Miete/Zins-Tilgung | E7: =D7*$E$5 -> 0 | F7: =D7*(1+G$5) -> 0 | G7: =F7*12 -> 0 | H7: =F7*(1+I$5) -> 0 | I7: =H7*12 -> 0 | J7: =H7*(1+K$5) -> 0 | K7: =J7*12 -> 0 | M7: nur private Wohnungsmiete | U7: Miete/Zins-Tilgung | V7: 845 | W7: =V7*$E$5 -> 10140 | X7: =V7/$V$29% -> 34.517974
C8: Nebenkosten | E8: =D8*$E$5 -> 0 | F8: =D8*(1+G$5) -> 0 | G8: =F8*12 -> 0 | H8: =F8*(1+I$5) -> 0 | I8: =H8*12 -> 0 | J8: =H8*(1+K$5) -> 0 | K8: =J8*12 -> 0 | M8: Heizung, Wasser, Strom, GEZ | U8: Nebenkosten | W8: =V8*$E$5 -> 0 | X8: =V8/$V$29% -> 0
C9: Telefon, Handy, Internet | E9: =D9*$E$5 -> 0 | F9: =D9*(1+G$5) -> 0 | G9: =F9*12 -> 0 | H9: =F9*(1+I$5) -> 0 | I9: =H9*12 -> 0 | J9: =H9*(1+K$5) -> 0 | K9: =J9*12 -> 0 | U9: Telefon, Handy, Internet | W9: =V9*$E$5 -> 0 | X9: =V9/$V$29% -> 0
B10: 1 | C10: SUMME WOHNKOSTEN | D10: =SUM(D7:D9) -> 0 | E10: =SUM(E7:E9) -> 0 | F10: =SUM(F7:F9) -> 0 | G10: =SUM(G7:G9) -> 0 | H10: =SUM(H7:H9) -> 0 | I10: =SUM(I7:I9) -> 0 | J10: =SUM(J7:J9) -> 0 | K10: =SUM(K7:K9) -> 0 | T10: 1 | U10: SUMME WOHNKOSTEN | V10: =SUM(V7:V9) -> 845 | W10: =SUM(W7:W9) -> 10140 | X10: =V10/$V$29% -> 34.517974
C11: Haushaltsgeld | E11: =D11*$E$5 -> 0 | F11: =D11*(1+G$5) -> 0 | G11: =F11*12 -> 0 | H11: =F11*(1+I$5) -> 0 | I11: =H11*12 -> 0 | J11: =H11*(1+K$5) -> 0 | K11: =J11*12 -> 0 | M11: Lebensmittel, Getränke | U11: Haushaltsgeld | V11: 486 | W11: =V11*$E$5 -> 5832 | X11: =V11/$V$29% -> 19.852941
C12: Kleidung, Körperpflege | E12: =D12*$E$5 -> 0 | F12: =D12*(1+G$5) -> 0 | G12: =F12*12 -> 0 | H12: =F12*(1+I$5) -> 0 | I12: =H12*12 -> 0 | J12: =H12*(1+K$5) -> 0 | K12: =J12*12 -> 0 | U12: Kleidung, Körperpflege | W12: =V12*$E$5 -> 0 | X12: =V12/$V$29% -> 0
C13: Freizeit, Sport, Hobby | E13: =D13*$E$5 -> 0 | F13: =D13*(1+G$5) -> 0 | G13: =F13*12 -> 0 | H13: =F13*(1+I$5) -> 0 | I13: =H13*12 -> 0 | J13: =H13*(1+K$5) -> 0 | K13: =J13*12 -> 0 | U13: Freizeit, Sport, Hobby | V13: 261 | W13: =V13*$E$5 -> 3132 | X13: =V13/$V$29% -> 10.661765
B14: 2 | C14: SUMME LEBENSHALTUNG | D14: =SUM(D11:D13) -> 0 | E14: =SUM(E11:E13) -> 0 | F14: =SUM(F11:F13) -> 0 | G14: =SUM(G11:G13) -> 0 | H14: =SUM(H11:H13) -> 0 | I14: =SUM(I11:I13) -> 0 | J14: =SUM(J11:J13) -> 0 | K14: =SUM(K11:K13) -> 0 | T14: 2 | U14: SUMME LEBENSHALTUNG | V14: =SUM(V11:V13) -> 747 | W14: =SUM(W11:W13) -> 8964 | X14: =V14/$V$29% -> 30.514706
C15: Krankenversicherung (KV+PV) | E15: =D15*$E$5 -> 0 | F15: =D15*(1+G$5) -> 0 | G15: =F15*12 -> 0 | H15: =F15*(1+I$5) -> 0 | I15: =H15*12 -> 0 | J15: =H15*(1+K$5) -> 0 | K15: =J15*12 -> 0 | M15: Welche Risiken sind zu versichern? | N15: KV+PV | O15: ='Ertragsv. 2025'!O23*Privatentnahmen!Q15/12 -> 0 | Q15: 0.1755 | U15: Krankenversicherung (KV+PV) | W15: =V15*$E$5 -> 0 | X15: =V15/$V$29% -> 0
C16: Berufsunfähigkeit, Unfall | E16: =D16*$E$5 -> 0 | F16: =D16*(1+G$5) -> 0 | G16: =F16*12 -> 0 | H16: =F16*(1+I$5) -> 0 | I16: =H16*12 -> 0 | J16: =H16*(1+K$5) -> 0 | K16: =J16*12 -> 0 | U16: Berufsunfähigkeit, Unfall | W16: =V16*$E$5 -> 0 | X16: =V16/$V$29% -> 0
C17: Altersvorsorge | E17: =D17*$E$5 -> 0 | F17: =D17*(1+G$5) -> 0 | G17: =F17*12 -> 0 | H17: =F17*(1+I$5) -> 0 | I17: =H17*12 -> 0 | J17: =H17*(1+K$5) -> 0 | K17: =J17*12 -> 0 | M17: Wie hoch muss die Versorgung sein? | N17: RV | O17: 85.05 | R17: Regelsätze nach SGB II +10% | U17: Altersvorsorge | V17: 300 | W17: =V17*$E$5 -> 3600 | X17: =V17/$V$29% -> 12.254902
C18: Sonst. Versicherungen | D18: 0 | E18: =D18*$E$5 -> 0 | F18: =D18*(1+G$5) -> 0 | G18: =F18*12 -> 0 | H18: =F18*(1+I$5) -> 0 | I18: =H18*12 -> 0 | J18: =H18*(1+K$5) -> 0 | K18: =J18*12 -> 0 | M18: Haftpflicht, Hausrat, Rechtsschutz | U18: Sonst. Versicherungen | V18: 56 | W18: =V18*$E$5 -> 672 | X18: =V18/$V$29% -> 2.2875817
B19: 3 | C19: SUMME VERSICHERUNGEN | D19: =SUM(D15:D18) -> 0 | E19: =SUM(E15:E18) -> 0 | F19: =SUM(F15:F18) -> 0 | G19: =SUM(G15:G18) -> 0 | H19: =SUM(H15:H18) -> 0 | I19: =SUM(I15:I18) -> 0 | J19: =SUM(J15:J18) -> 0 | K19: =SUM(K15:K18) -> 0 | T19: 3 | U19: SUMME VERSICHERUNGEN | V19: =SUM(V15:V18) -> 356 | W19: =SUM(W15:W18) -> 4272 | X19: =V19/$V$29% -> 14.542484
C20: KfZ-Kosten | E20: =D20*$E$5 -> 0 | F20: =D20*(1+G$5) -> 0 | G20: =F20*12 -> 0 | H20: =F20*(1+I$5) -> 0 | I20: =H20*12 -> 0 | J20: =H20*(1+K$5) -> 0 | K20: =J20*12 -> 0 | M20: Steuern, Versicherung, lfd. Kosten | O20: =P20*Q20 -> 0 | P20: 0 | Q20: =399*110% -> 438.9 | U20: KfZ-Kosten | W20: =V20*$E$5 -> 0 | X20: =V20/$V$29% -> 0
C21: Bahncard, ÖPNV | E21: =D21*$E$5 -> 0 | F21: =D21*(1+G$5) -> 0 | G21: =F21*12 -> 0 | H21: =F21*(1+I$5) -> 0 | I21: =H21*12 -> 0 | J21: =H21*(1+K$5) -> 0 | K21: =J21*12 -> 0 | O21: =P21*Q21 -> 792 | P21: 2 | Q21: =360*110% -> 396 | U21: Bahncard, ÖPNV | W21: =V21*$E$5 -> 0 | X21: =V21/$V$29% -> 0
B22: 4 | C22: SUMME FAHRTKOSTEN | D22: =SUM(D20:D21) -> 0 | E22: =SUM(E20:E21) -> 0 | F22: =SUM(F20:F21) -> 0 | G22: =SUM(G20:G21) -> 0 | H22: =SUM(H20:H21) -> 0 | I22: =SUM(I20:I21) -> 0 | J22: =SUM(J20:J21) -> 0 | K22: =SUM(K20:K21) -> 0 | O22: =P22*Q22 -> 0 | Q22: =320*110% -> 352 | T22: 4 | U22: SUMME FAHRTKOSTEN | V22: =SUM(V20:V21) -> 0 | W22: =SUM(W20:W21) -> 0 | X22: =V22/$V$29% -> 0
C23: Unterhaltsverpflichtungen | E23: =D23*$E$5 -> 0 | F23: =D23*(1+G$5) -> 0 | G23: =F23*12 -> 0 | H23: =F23*(1+I$5) -> 0 | I23: =H23*12 -> 0 | J23: =H23*(1+K$5) -> 0 | K23: =J23*12 -> 0 | O23: =P23*Q23 -> 0 | Q23: =302*110% -> 332.2 | U23: Unterhaltsverpflichtungen | W23: =V23*$E$5 -> 0 | X23: =V23/$V$29% -> 0
C24: Private Kredite, Kontoführung | E24: =D24*$E$5 -> 0 | F24: =D24*(1+G$5) -> 0 | G24: =F24*12 -> 0 | H24: =F24*(1+I$5) -> 0 | I24: =H24*12 -> 0 | J24: =H24*(1+K$5) -> 0 | K24: =J24*12 -> 0 | O24: =P24*Q24 -> 293.7 | P24: 1 | Q24: =267*110% -> 293.7 | U24: Private Kredite, Kontoführung | V24: 57 | W24: =V24*$E$5 -> 684 | X24: =V24/$V$29% -> 2.3284314
C25: Kindergarten, Schule | E25: =D25*$E$5 -> 0 | F25: =D25*(1+G$5) -> 0 | G25: =F25*12 -> 0 | H25: =F25*(1+I$5) -> 0 | I25: =H25*12 -> 0 | J25: =H25*(1+K$5) -> 0 | K25: =J25*12 -> 0 | O25: =P25*Q25 -> 257.4 | P25: 1 | Q25: =234*110% -> 257.4 | U25: Kindergarten, Schule | W25: =V25*$E$5 -> 0 | X25: =V25/$V$29% -> 0
C26: Sonstiges | D26: 0 | E26: =D26*$E$5 -> 0 | F26: =D26*(1+G$5) -> 0 | G26: =F26*12 -> 0 | H26: =F26*(1+I$5) -> 0 | I26: =H26*12 -> 0 | U26: Sonstiges/Kauf v.Möbeln usw | V26: 124 | W26: =V26*$E$5 -> 1488 | X26: =V26/$V$29% -> 5.0653595
C27: Sparen | E27: =D27*$E$5 -> 0 | F27: =D27*(1+G$5) -> 0 | G27: =F27*12 -> 0 | H27: =F27*(1+I$5) -> 0 | I27: =H27*12 -> 0 | J27: =H27*(1+K$5) -> 0 | K27: =J27*12 -> 0 | M27: Urlaub, Anschaffungen | U27: Sparen | V27: 319 | W27: =V27*$E$5 -> 3828 | X27: =V27/$V$29% -> 13.031046
B28: 5 | C28: SUMME SONST. AUSGABEN | D28: =SUM(D23:D27) -> 0 | E28: =SUM(E23:E27) -> 0 | F28: =SUM(F23:F27) -> 0 | G28: =SUM(G23:G27) -> 0 | H28: =SUM(H23:H27) -> 0 | I28: =SUM(I23:I27) -> 0 | J28: =SUM(J23:J27) -> 0 | K28: =SUM(K23:K27) -> 0 | T28: 5 | U28: SUMME SONST. AUSGABEN | V28: =SUM(V23:V27) -> 500 | W28: =SUM(W23:W27) -> 6000 | X28: =V28/$V$29% -> 20.424837
C29: SUMME AUSGABEN | D29: =SUM(D28,D22,D19,D14,D10) -> 0 | E29: =SUM(E28,E22,E19,E14,E10) -> 0 | F29: =SUM(F28,F22,F19,F14,F10) -> 0 | G29: =SUM(G28,G22,G19,G14,G10) -> 0 | H29: =SUM(H28,H22,H19,H14,H10) -> 0 | I29: =SUM(I28,I22,I19,I14,I10) -> 0 | J29: =SUM(J28,J22,J19,J14,J10) -> 0 | K29: =SUM(K28,K22,K19,K14,K10) -> 0 | O29: =SUM(O7:O28) -> 1428.15 | U29: SUMME AUSGABEN | V29: =SUM(V28,V22,V19,V14,V10) -> 2448 | W29: =SUM(W28,W22,W19,W14,W10) -> 29376 | X29: =V29/$V$29% -> 100
C30: Kindergeld, Unterhalt | D30: 0 | E30: =D30*$E$5 -> 0 | F30: =D30 -> 0 | G30: =F30*12 -> 0 | H30: =F30 -> 0 | I30: =H30*12 -> 0 | J30: =H30 -> 0 | K30: =J30*12 -> 0
C31: Netto-Einkommen PartnerIn | E31: =D31*$E$5 -> 0 | F31: =D31 -> 0 | G31: =F31*12 -> 0 | H31: =F31 -> 0 | I31: =H31*12 -> 0 | J31: =H31 -> 0 | K31: =J31*12 -> 0
C32: Nebentätigkeit, Sonstiges | E32: =D32*$E$5 -> 0 | F32: =D32 -> 0 | G32: =F32*12 -> 0 | H32: =F32 -> 0 | I32: =H32*12 -> 0 | J32: =H32 -> 0 | K32: =J32*12 -> 0
C33: SUMME EINKOMMEN | D33: =SUM(D30:D32) -> 0 | E33: =SUM(E30:E32) -> 0 | F33: =SUM(F30:F32) -> 0 | G33: =SUM(G30:G32) -> 0 | H33: =SUM(H30:H32) -> 0 | I33: =SUM(I30:I32) -> 0 | J33: =SUM(J30:J32) -> 0 | K33: =SUM(K30:K32) -> 0
J34: =J46*J47/12 -> 0 | K34: =J34*12 -> 0
C35: SUMME DER PRIVATENTNAHMEN | D35: =D29-D33+D34 -> 0 | E35: =E29-E33+E34 -> 0 | F35: =F29-F33+F34 -> 0 | G35: =G29-G33+G34 -> 0 | H35: =H29-H33+H34 -> 0 | I35: =I29-I33+I34 -> 0 | J35: =J29-J33+J34 -> 0 | K35: =K29-K33+K34 -> 0

Sheet Ertragsv. 2025
B1: ERTRAGSVORSCHAU 1. Planjahr | E1: =ZusammenführErgebn!C3 -> 2025 | H1: =Deckblatt!C5 -> Max Mustermann
A2: Durchschn. Warenein-satz | B2: ALLE ANGABEN NETTO | C2: =VLOOKUP(Deckblatt!$C$8,Deckblatt!$G$99:$R$110,1,FALSE) -> Jan. | D2: =VLOOKUP(Deckblatt!$C$8,Deckblatt!$G$99:$R$110,2,FALSE) -> Febr. | E2: =VLOOKUP(Deckblatt!$C$8,Deckblatt!$G$99:$R$110,3,FALSE) -> März | F2: =VLOOKUP(Deckblatt!$C$8,Deckblatt!$G$99:$R$110,4,FALSE) -> April | G2: =VLOOKUP(Deckblatt!$C$8,Deckblatt!$G$99:$R$110,5,FALSE) -> Mai | H2: =VLOOKUP(Deckblatt!$C$8,Deckblatt!$G$99:$R$110,6,FALSE) -> Juni | I2: =VLOOKUP(Deckblatt!$C$8,Deckblatt!$G$99:$R$110,7,FALSE) -> Juli | J2: =VLOOKUP(Deckblatt!$C$8,Deckblatt!$G$99:$R$110,8,FALSE) -> Aug. | K2: =VLOOKUP(Deckblatt!$C$8,Deckblatt!$G$99:$R$110,9,FALSE) -> Sept. | L2: =VLOOKUP(Deckblatt!$C$8,Deckblatt!$G$99:$R$110,10,FALSE) -> Okt. | M2: =VLOOKUP(Deckblatt!$C$8,Deckblatt!$G$99:$R$110,11,FALSE) -> Nov. | N2: =VLOOKUP(Deckblatt!$C$8,Deckblatt!$G$99:$R$110,12,FALSE) -> Dez. | O2: SUMME | P2: % | Q2: Branchen-vergl. | R2: ERLÄUTERUNGEN / KOMMENTARE
B3: Umsatz/ Erlöse | C3: ='UmstzPlan 1.-3.Jahr'!E19 -> 0 | D3: ='UmstzPlan 1.-3.Jahr'!G19 -> 0 | E3: ='UmstzPlan 1.-3.Jahr'!I19 -> 0 | F3: ='UmstzPlan 1.-3.Jahr'!K19 -> 0 | G3: ='UmstzPlan 1.-3.Jahr'!M19 -> 0 | H3: ='UmstzPlan 1.-3.Jahr'!O19 -> 0 | I3: ='UmstzPlan 1.-3.Jahr'!Q19 -> 0 | J3: ='UmstzPlan 1.-3.Jahr'!S19 -> 0 | K3: ='UmstzPlan 1.-3.Jahr'!U19 -> 0 | L3: ='UmstzPlan 1.-3.Jahr'!W19 -> 0 | M3: ='UmstzPlan 1.-3.Jahr'!Y19 -> 0 | N3: ='UmstzPlan 1.-3.Jahr'!AA19 -> 0 | O3: =SUM(C3:N3) -> 0 | P3: 100
A4: 0.23 | B4: ./.Materialeinsatz | C4: =C3*$A$4 -> 0 | D4: =D3*$A$4 -> 0 | E4: =E3*$A$4 -> 0 | F4: =F3*$A$4 -> 0 | G4: =G3*$A$4 -> 0 | H4: =H3*$A$4 -> 0 | I4: =I3*$A$4 -> 0 | J4: =J3*$A$4 -> 0 | ... N4: =N3*$A$4 -> 0 | O4: =SUM(C4:N4) -> 0 | P4: =O4/$O$3% -> #DIV/0! | R4: Einkaufsliste erarbeiten!
B5: ./. Kosten:
B6: Raumkosten | O6: =SUM(C6:N6) -> 0 | P6: =O6/$O$3% -> #DIV/0! | R6: Beispiel: Büromiete 12% der Wohnung
B7: Kfz Steuer | O7: =SUM(C7:N7) -> 0 | P7: =O7/$O$3% -> #DIV/0! | R7: anteilig gem.Nutzung
B8: Kraftfahrzeugkosten | O8: =SUM(C8:N8) -> 0 | P8: =O8/$O$3% -> #DIV/0! | R8: gem.geschätz.mtl Kilometerleistung
B9: Leasing | C9: =Finanz_AfA_Investitionen!$H28 -> 0 | D9: =Finanz_AfA_Investitionen!$H28 -> 0 | E9: =Finanz_AfA_Investitionen!$H28 -> 0 | F9: =Finanz_AfA_Investitionen!$H28 -> 0 | G9: =Finanz_AfA_Investitionen!$H28 -> 0 | H9: =Finanz_AfA_Investitionen!$H28 -> 0 | I9: =Finanz_AfA_Investitionen!$H28 -> 0 | J9: =Finanz_AfA_Investitionen!$H28 -> 0 | ... N9: =Finanz_AfA_Investitionen!$H28 -> 0 | O9: =SUM(C9:N9) -> 0 | P9: =O9/$O$3% -> #DIV/0!
B10: Werbe- und Reisekosten | O10: =SUM(C10:N10) -> 0 | P10: =O10/$O$3% -> #DIV/0! | R10: Marketing-Aktivitätenplan erstellt?
B11: Telefon, Telefax, Internet | O11: =SUM(C11:N11) -> 0 | P11: =O11/$O$3% -> #DIV/0!
B12: Bürobedarf | O12: =SUM(C12:N12) -> 0 | P12: =O12/$O$3% -> #DIV/0!
B13: Rechts- und Beratungskosten | O13: =SUM(C13:N13) -> 0 | P13: =O13/$O$3% -> #DIV/0! | R13: Steuerberater vorhanden? Beitrag Berufsverb.
B14: Versicherungen/Beiträge | O14: =SUM(C14:N14) -> 0 | P14: =O14/$O$3% -> #DIV/0! | R14: Was muss versichert werden? Welche Risiken
B15: Reparaturen/Instandhaltung | O15: =SUM(C15:N15) -> 0 | P15: =O15/$O$3% -> #DIV/0!
B16: sonstiger Betriebsaufwand | O16: =SUM(C16:N16) -> 0 | P16: =O16/$O$3% -> #DIV/0!
B17: Zinsaufwand | C17: =Finanz_AfA_Investitionen!$F38-Finanz_AfA_Investitionen!$F37+'Mikrostarter Geschäftsplan'!D16 -> 0 | D17: =Finanz_AfA_Investitionen!$F38-Finanz_AfA_Investitionen!$F37+'Mikrostarter Geschäftsplan'!D17 -> 0 | E17: =Finanz_AfA_Investitionen!$F38-Finanz_AfA_Investitionen!$F37+'Mikrostarter Geschäftsplan'!D18 -> 0 | F17: =Finanz_AfA_Investitionen!$F38-Finanz_AfA_Investitionen!$F37+'Mikrostarter Geschäftsplan'!D20 -> 0 | G17: =Finanz_AfA_Investitionen!$F38-Finanz_AfA_Investitionen!$F37+'Mikrostarter Geschäftsplan'!D21 -> 0 | H17: =Finanz_AfA_Investitionen!$F38-Finanz_AfA_Investitionen!$F37+'Mikrostarter Geschäftsplan'!D22 -> 0 | I17: =Finanz_AfA_Investitionen!$F38-Finanz_AfA_Investitionen!$F37+'Mikrostarter Geschäftsplan'!D24 -> 0 | J17: =Finanz_AfA_Investitionen!$F38-Finanz_AfA_Investitionen!$F37+'Mikrostarter Geschäftsplan'!D25 -> 0 | K17: =Finanz_AfA_Investitionen!$F38-Finanz_AfA_Investitionen!$F37+'Mikrostarter Geschäftsplan'!D26 -> 0 | L17: =Finanz_AfA_Investitionen!$F38-Finanz_AfA_Investitionen!$F37+'Mikrostarter Geschäftsplan'!D28 -> 0 | M17: =Finanz_AfA_Investitionen!$F38-Finanz_AfA_Investitionen!$F37+'Mikrostarter Geschäftsplan'!D29 -> 0 | N17: =Finanz_AfA_Investitionen!$F38-Finanz_AfA_Investitionen!$F37+'Mikrostarter Geschäftsplan'!D30 -> 0 | O17: =SUM(C17:N17) -> 0 | P17: =O17/$O$3% -> #DIV/0! | R17: Investitiosplanung vorhanden?
B18: PersonalkostenAGA | C18: =ArbStd_MA!$I$76+ArbStd_MA!$I$81 -> 0 | D18: =ArbStd_MA!$I$76+ArbStd_MA!$I$81 -> 0 | E18: =ArbStd_MA!$I$76+ArbStd_MA!$I$81 -> 0 | F18: =ArbStd_MA!$I$76+ArbStd_MA!$I$81 -> 0 | G18: =ArbStd_MA!$I$76+ArbStd_MA!$I$81 -> 0 | H18: =ArbStd_MA!$I$76+ArbStd_MA!$I$81 -> 0 | I18: =ArbStd_MA!$I$76+ArbStd_MA!$I$81 -> 0 | J18: =ArbStd_MA!$I$76+ArbStd_MA!$I$81 -> 0 | ... N18: =ArbStd_MA!$I$76+ArbStd_MA!$I$81 -> 0 | O18: =SUM(C18:N18) -> 0 | P18: =O18/$O$3% -> #DIV/0!
B19: Einmalige (Gründungs)kosten | O19: =SUM(C19:N19) -> 0 | P19: =O19/$O$3% -> #DIV/0!
B20: Summe Aufwendungen | C20: =SUM(C4:C19) -> 0 | D20: =SUM(D4:D19) -> 0 | E20: =SUM(E4:E19) -> 0 | F20: =SUM(F4:F19) -> 0 | G20: =SUM(G4:G19) -> 0 | H20: =SUM(H4:H19) -> 0 | I20: =SUM(I4:I19) -> 0 | J20: =SUM(J4:J19) -> 0 | ... N20: =SUM(N4:N19) -> 0 | O20: =SUM(C20:N20) -> 0 | P20: =O20/$O$3% -> #DIV/0!
B21: Betriebsergebnis | C21: =C3-C20 -> 0 | D21: =D3-D20 -> 0 | E21: =E3-E20 -> 0 | F21: =F3-F20 -> 0 | G21: =G3-G20 -> 0 | H21: =H3-H20 -> 0 | I21: =I3-I20 -> 0 | J21: =J3-J20 -> 0 | ... N21: =N3-N20 -> 0 | O21: =SUM(C21:N21) -> 0 | P21: =O21/$O$3% -> #DIV/0!
B22: ./. Abschreibungen | C22: =Finanz_AfA_Investitionen!$F28 -> 0 | D22: =Finanz_AfA_Investitionen!$F28 -> 0 | E22: =Finanz_AfA_Investitionen!$F28 -> 0 | F22: =Finanz_AfA_Investitionen!$F28 -> 0 | G22: =Finanz_AfA_Investitionen!$F28 -> 0 | H22: =Finanz_AfA_Investitionen!$F28 -> 0 | I22: =Finanz_AfA_Investitionen!F28 -> 0 | J22: =Finanz_AfA_Investitionen!F28 -> 0 | K22: =Finanz_AfA_Investitionen!F28 -> 0 | L22: =Finanz_AfA_Investitionen!F28 -> 0 | M22: =Finanz_AfA_Investitionen!F28 -> 0 | N22: =Finanz_AfA_Investitionen!F28 -> 0 | O22: =SUM(C22:N22) -> 0 | P22: =O22/$O$3% -> #DIV/0!
B23: Gewinn/Verlust | C23: =C21-C22 -> 0 | D23: =D21-D22 -> 0 | E23: =E21-E22 -> 0 | F23: =F21-F22 -> 0 | G23: =G21-G22 -> 0 | H23: =H21-H22 -> 0 | I23: =I21-I22 -> 0 | J23: =J21-J22 -> 0 | ... O23: =O21-O22 -> 0 | P23: =O23/$O$3% -> #DIV/0!
B24: Aufgelaufene Werte | C24: =C23 -> 0 | D24: =C23+D23 -> 0 | E24: =C23+D23+E23 -> 0 | F24: =C23+D23+E23+F23 -> 0 | G24: =C23+D23+E23+F23+G23 -> 0 | H24: =C23+D23+E23+F23+G23+H23 -> 0 | I24: =C23+D23+E23+F23+G23+H23+I23 -> 0 | J24: =C23+D23+E23+F23+G23+H23+I23+J23 -> 0 | K24: =C23+D23+E23+F23+G23+H23+I23+J23+K23 -> 0 | L24: =C23+D23+E23+F23+G23+H23+I23+J23+K23+L23 -> 0 | M24: =C23+D23+E23+F23+G23+H23+I23+J23+K23+L23+M23 -> 0 | N24: =C23+D23+E23+F23+G23+H23+I23+J23+K23+L23+M23+N23 -> 0 | P24: =O24/$O$3% -> #DIV/0!
B25: Kalk. Steuern(ESt/Soli/GeSt) | C25: =IF($K$32=1,C23*$I$32,IF($K$32=2,C23*$I$33)) -> 0 | D25: =IF($K$32=1,D23*$I$32,IF($K$32=2,D23*$I$33)) -> 0 | E25: =IF($K$32=1,E23*$I$32,IF($K$32=2,E23*$I$33)) -> 0 | F25: =IF($K$32=1,F23*$I$32,IF($K$32=2,F23*$I$33)) -> 0 | G25: =IF($K$32=1,G23*$I$32,IF($K$32=2,G23*$I$33)) -> 0 | H25: =IF($K$32=1,H23*$I$32,IF($K$32=2,H23*$I$33)) -> 0 | I25: =IF($K$32=1,I23*$I$32,IF($K$32=2,I23*$I$33)) -> 0 | J25: =IF($K$32=1,J23*$I$32,IF($K$32=2,J23*$I$33)) -> 0 | ... N25: =IF($K$32=1,N23*$I$32,IF($K$32=2,N23*$I$33)) -> 0 | O25: =SUM(C25:N25) -> 0 | P25: =O25/$O$3% -> #DIV/0!
B26: Gewinn/Verlust n.Steuern | C26: =C23-C25 -> 0 | D26: =D23-D25 -> 0 | E26: =E23-E25 -> 0 | F26: =F23-F25 -> 0 | G26: =G23-G25 -> 0 | H26: =H23-H25 -> 0 | I26: =I23-I25 -> 0 | J26: =J23-J25 -> 0 | ... N26: =N23-N25 -> 0 | O26: =SUM(C26:N26) -> 0 | P26: =O26/$O$3% -> #DIV/0!
B27: UnternehmerInnen-Lohn | C27: =$M44 -> 0 | D27: =$M44 -> 0 | E27: =$M44 -> 0 | F27: =$M44 -> 0 | G27: =$M44 -> 0 | H27: =$M44 -> 0 | I27: =$M44 -> 0 | J27: =$M44 -> 0 | ... N27: =$M44 -> 0 | O27: =SUM(C27:N27) -> 0 | P27: =O27/$O$3% -> #DIV/0!
B28: Darstellung Risikobetrag Umsatzlose Zeit | L28: in % vom Umsatz | O28: =(O20-O4+O22)*Q43 -> 0 | P28: =O28/$O$3% -> #DIV/0!
B29: Darstellung Risikobetrag Saisonverkäufe | L29: in % vom Wareneinkauf | O29: =O4*Q42 -> 0 | P29: =O29/$O$3% -> #DIV/0!
B31: Steuern individuell | C31: je nach Einkommen für den Mindeststundensatz | I31: =C32+E32 -> 0.0844
B32: Steuern Einzelfirma | C32: 0.08 | D32: EST | E32: =C32*5.5% -> 0.0044 | F32: Soli | G32: 0 | H32: GeSt | I32: =C32+E32+G32 -> 0.0844 | K32: 1
B33: Steuern GmbH | C33: 0.15 | D33: KöSt | E33: =C33*5.5% -> 0.00825 | F33: Soli | G33: 0.14 | H33: GeSt | I33: =C33+E33+G33 -> 0.29825
B36: GESAMTKALKULATION | C36: 1) PRIVATE KOSTEN + 2) GEWERBLICHE KOSTEN + WARENEINSATZ + 3) 3% RISIKOZUSCHLAG UNTERNEHM. TÄTIGKEIT (SOZIALE SICHERUNG) + 4) 10% EIGENKAPITALVERZINSUNG + 5) KALKULATORISCHE STEUERN + 6) 5% REINGEWINNANSPRUCH ) +7) 2% RISIKOZUSCHLAG FÜR GARANTIE / GEWÄHRLEISTUNG/SCHWUND UND VORSORGE FÜR FORDERUNGSVERLUSTE, +8) RISIKOZUSCHLAG FÜR SAISON-/SONDERVERKÄUFE / NACHLÄSSE +9) RISIKOZUSCHLAG FÜR UNTERAUSLASTUNG UND UMSATZLOSE ZEIT
C37: 1) | D37: + 2) | E37: + 3) | F37: + 4) | G37: + 5) | H37: + 6) | I37: + 7) | J37: +8) | K37: +9) | L37: prod. Arbeitstd. | M37: Mindestumsatz
B38: Mindestumsatz | C38: =Privatentnahmen!D35 -> 0 | D38: =(O20+O22)/12 -> 0 | E38: =(O3/12)*Q38 -> 0 | F38: =(Finanz_AfA_Investitionen!C31*'Ertragsv. 2025'!Q39)/12 -> 0 | G38: =O25/12 -> 0 | H38: =O3/12*Q40 -> 0 | I38: =O3/12*Q41 -> 0 | J38: =O29/12 -> 0 | K38: =IF(O4>1,(O28/12),IF(O4<1,0)) -> 0 | M38: =SUM(C38:K38) -> 0 | P38: 3) | Q38: 0.03
C39: 1) | D39: + 2a) | E39: + 3) | F39: + 4) | G39: + 5) | H39: + 6) | I39: +7) | J39: +8) | K39: +9) | L39: =IF(ArbStd_MA!$E$33>=1,ArbStd_MA!$E$33,IF(ArbStd_MA!$E$33<=1,ArbStd_MA!$D$23)) -> 144 | M39: Stundensatz | P39: 4) | Q39: 0.05
B40: Mindeststundensatz | C40: =Privatentnahmen!D35 -> 0 | D40: =(O20-O4+O22)/12 -> 0 | G40: =C40*I31 -> 0 | L40: =IF(ArbStd_MA!$E$33>=1,ArbStd_MA!$E$33,IF(ArbStd_MA!$E$33<=1,ArbStd_MA!$D$23)) -> 144 | M40: =(C40+D40+G40+K40)/L40/ArbStd_MA!F49 -> 0 | P40: 6) | Q40: 0.05
B41: Stundenverkaufssatz | C41: =Privatentnahmen!D35 -> 0 | D41: =D40 -> 0 | E41: =(O3/12)*Q38 -> 0 | F41: =(Finanz_AfA_Investitionen!C31*'Ertragsv. 2025'!Q39)/12 -> 0 | G41: =O25/12 -> 0 | H41: =O3/12*Q40 -> 0 | I41: =O3/12*Q41 -> 0 | L41: =IF(ArbStd_MA!$E$33>=1,ArbStd_MA!$E$33,IF(ArbStd_MA!$E$33<=1,ArbStd_MA!$D$23)) -> 144 | M41: =(C41+D41+E41+F41+G41+H41+I41+J41+K41)/L41/ArbStd_MA!F49 -> 0 | P41: 7) | Q41: 0.02
B42: relative Stundensatzdifferenz | M42: =ROUND((M41-M40)/M40*100,1)& " %" -> #DIV/0! | P42: 8) | Q42: 0.1
B43: Rohaufschlag im Handel % | C43: =C41 -> 0 | D43: =D41 -> 0 | E43: =E41 -> 0 | F43: =F41 -> 0 | G43: =G41 -> 0 | H43: =H41 -> 0 | I43: =I41 -> 0 | J43: =J38 -> 0 | K43: =K38 -> 0 | M43: =IF(O4<1,0,(C43+D43+E43+F43+G43+H43+I43+J43+K43)*100*12/O4) -> 0 | P43: 9) | Q43: 0.15
...

Sheet Ertragsv. 2026
B1: ERTRAGSVORSCHAU 2.Planjahr | E1: =ZusammenführErgebn!D3 -> 2026 | H1: =Deckblatt!C5 -> Max Mustermann
A2: Durchschn. Warenein-satz | B2: ALLE ANGABEN NETTO | C2: ='Ertragsv. 2025'!C2 -> Jan. | D2: ='Ertragsv. 2025'!D2 -> Febr. | E2: ='Ertragsv. 2025'!E2 -> März | F2: ='Ertragsv. 2025'!F2 -> April | G2: ='Ertragsv. 2025'!G2 -> Mai | H2: ='Ertragsv. 2025'!H2 -> Juni | I2: ='Ertragsv. 2025'!I2 -> Juli | J2: ='Ertragsv. 2025'!J2 -> Aug. | ... N2: ='Ertragsv. 2025'!N2 -> Dez. | O2: SUMME | P2: % | Q2: Branchen-vergl. | R2: ERLÄUTERUNGEN / KOMMENTARE
B3: Umsatz/ Erlöse | C3: ='UmstzPlan 1.-3.Jahr'!E38 -> 0 | D3: ='UmstzPlan 1.-3.Jahr'!G38 -> 0 | E3: ='UmstzPlan 1.-3.Jahr'!I38 -> 0 | F3: ='UmstzPlan 1.-3.Jahr'!K38 -> 0 | G3: ='UmstzPlan 1.-3.Jahr'!M38 -> 0 | H3: ='UmstzPlan 1.-3.Jahr'!O38 -> 0 | I3: ='UmstzPlan 1.-3.Jahr'!Q38 -> 0 | J3: ='UmstzPlan 1.-3.Jahr'!S38 -> 0 | K3: ='UmstzPlan 1.-3.Jahr'!U38 -> 0 | L3: ='UmstzPlan 1.-3.Jahr'!W38 -> 0 | M3: ='UmstzPlan 1.-3.Jahr'!Y38 -> 0 | N3: ='UmstzPlan 1.-3.Jahr'!AA38 -> 0 | O3: =SUM(C3:N3) -> 0 | P3: 100
A4: 0.12 | B4: ./.Materialeinsatz | C4: =C3*$A$4 -> 0 | D4: =D3*$A$4 -> 0 | E4: =E3*$A$4 -> 0 | F4: =F3*$A$4 -> 0 | G4: =G3*$A$4 -> 0 | H4: =H3*$A$4 -> 0 | I4: =I3*$A$4 -> 0 | J4: =J3*$A$4 -> 0 | ... N4: =N3*$A$4 -> 0 | O4: =SUM(C4:N4) -> 0 | P4: =O4/$O$3% -> #DIV/0!
B5: ./. Kosten:
B6: Raumkosten | D6: 0 | E6: 0 | F6: 0 | G6: 0 | H6: 0 | I6: 0 | J6: 0 | K6: 0 | L6: 0 | M6: 0 | N6: 0 | O6: =SUM(C6:N6) -> 0 | P6: =O6/$O$3% -> #DIV/0! | R6: Beispiel: Büromiete 12% der Wohnung
B7: Kfz Steuer | C7: 0 | D7: 0 | E7: 0 | F7: 0 | G7: 0 | H7: 0 | I7: 0 | J7: 0 | K7: 0 | L7: 0 | M7: 0 | N7: 0 | O7: =SUM(C7:N7) -> 0 | P7: =O7/$O$3% -> #DIV/0! | R7: anteilig gem.Nutzung
B8: Kraftfahrzeugkosten | C8: 0 | D8: 0 | E8: 0 | F8: 0 | G8: 0 | H8: 0 | I8: 0 | J8: 0 | K8: 0 | L8: 0 | M8: 0 | N8: 0 | O8: =SUM(C8:N8) -> 0 | P8: =O8/$O$3% -> #DIV/0! | R8: gem.geschätz.mtl Kilometerleistung
B9: Leasing | C9: =Finanz_AfA_Investitionen!$H28 -> 0 | D9: =Finanz_AfA_Investitionen!$H28 -> 0 | E9: =Finanz_AfA_Investitionen!$H28 -> 0 | F9: =Finanz_AfA_Investitionen!$H28 -> 0 | G9: =Finanz_AfA_Investitionen!$H28 -> 0 | H9: =Finanz_AfA_Investitionen!$H28 -> 0 | I9: =Finanz_AfA_Investitionen!$H28 -> 0 | J9: =Finanz_AfA_Investitionen!$H28 -> 0 | ... N9: =Finanz_AfA_Investitionen!$H28 -> 0 | O9: =SUM(C9:N9) -> 0 | P9: =O9/$O$3% -> #DIV/0!
B10: Werbe- und Reisekosten | O10: =SUM(C10:N10) -> 0 | P10: =O10/$O$3% -> #DIV/0!
B11: Telefon, Telefax, Internet | O11: =SUM(C11:N11) -> 0 | P11: =O11/$O$3% -> #DIV/0!
B12: Bürobedarf | O12: =SUM(C12:N12) -> 0 | P12: =O12/$O$3% -> #DIV/0!
B13: Rechts- und Beratungskosten | O13: =SUM(C13:N13) -> 0 | P13: =O13/$O$3% -> #DIV/0!
B14: Versicherungen/Beiträge | O14: =SUM(C14:N14) -> 0 | P14: =O14/$O$3% -> #DIV/0!
B15: Reparaturen/Instandhaltung | O15: =SUM(C15:N15) -> 0 | P15: =O15/$O$3% -> #DIV/0!
B16: sonstiger Betriebsaufwand | O16: =SUM(C16:N16) -> 0 | P16: =O16/$O$3% -> #DIV/0!
B17: Zinsaufwand | C17: =Finanz_AfA_Investitionen!$H$38-Finanz_AfA_Investitionen!H37+'Mikrostarter Geschäftsplan'!D33 -> 0 | D17: =Finanz_AfA_Investitionen!$H$38-Finanz_AfA_Investitionen!H37+'Mikrostarter Geschäftsplan'!D34 -> 0 | E17: =Finanz_AfA_Investitionen!$H$38-Finanz_AfA_Investitionen!H37+'Mikrostarter Geschäftsplan'!D35 -> 0 | F17: =Finanz_AfA_Investitionen!$H$38-Finanz_AfA_Investitionen!H37+'Mikrostarter Geschäftsplan'!D36 -> 0 | G17: =Finanz_AfA_Investitionen!$H$38-Finanz_AfA_Investitionen!H37+'Mikrostarter Geschäftsplan'!D37 -> 0 | H17: =Finanz_AfA_Investitionen!$H$38-Finanz_AfA_Investitionen!H37+'Mikrostarter Geschäftsplan'!D38 -> 0 | I17: =Finanz_AfA_Investitionen!$H$38-Finanz_AfA_Investitionen!H37+'Mikrostarter Geschäftsplan'!D39 -> 0 | J17: =Finanz_AfA_Investitionen!$H$38-Finanz_AfA_Investitionen!H37+'Mikrostarter Geschäftsplan'!D40 -> 0 | K17: =Finanz_AfA_Investitionen!$H$38-Finanz_AfA_Investitionen!H37+'Mikrostarter Geschäftsplan'!D41 -> 0 | L17: =Finanz_AfA_Investitionen!$H$38-Finanz_AfA_Investitionen!H37+'Mikrostarter Geschäftsplan'!D42 -> 0 | M17: =Finanz_AfA_Investitionen!$H$38-Finanz_AfA_Investitionen!H37+'Mikrostarter Geschäftsplan'!D43 -> 0 | N17: =Finanz_AfA_Investitionen!$H$38-Finanz_AfA_Investitionen!H37+'Mikrostarter Geschäftsplan'!D44 -> 0 | O17: =SUM(C17:N17) -> 0 | P17: =O17/$O$3% -> #DIV/0!
B18: PersonalkostenAGA | C18: =ArbStd_MA!$I$94+ArbStd_MA!$I$99 -> 0 | D18: =ArbStd_MA!$I$94+ArbStd_MA!$I$99 -> 0 | E18: =ArbStd_MA!$I$94+ArbStd_MA!$I$99 -> 0 | F18: =ArbStd_MA!$I$94+ArbStd_MA!$I$99 -> 0 | G18: =ArbStd_MA!$I$94+ArbStd_MA!$I$99 -> 0 | H18: =ArbStd_MA!$I$94+ArbStd_MA!$I$99 -> 0 | I18: =ArbStd_MA!$I$94+ArbStd_MA!$I$99 -> 0 | J18: =ArbStd_MA!$I$94+ArbStd_MA!$I$99 -> 0 | ... N18: =ArbStd_MA!$I$94+ArbStd_MA!$I$99 -> 0 | O18: =SUM(C18:N18) -> 0 | P18: =O18/$O$3% -> #DIV/0!
P19: =O19/$O$3% -> #DIV/0!
B20: Summe Aufwendungen | C20: =SUM(C4:C19) -> 0 | D20: =SUM(D4:D19) -> 0 | E20: =SUM(E4:E19) -> 0 | F20: =SUM(F4:F19) -> 0 | G20: =SUM(G4:G19) -> 0 | H20: =SUM(H4:H19) -> 0 | I20: =SUM(I4:I19) -> 0 | J20: =SUM(J4:J19) -> 0 | ... N20: =SUM(N4:N19) -> 0 | O20: =SUM(C20:N20) -> 0 | P20: =O20/$O$3% -> #DIV/0!
B21: Betriebsergebnis | C21: =C3-C20 -> 0 | D21: =D3-D20 -> 0 | E21: =E3-E20 -> 0 | F21: =F3-F20 -> 0 | G21: =G3-G20 -> 0 | H21: =H3-H20 -> 0 | I21: =I3-I20 -> 0 | J21: =J3-J20 -> 0 | ... N21: =N3-N20 -> 0 | O21: =SUM(C21:N21) -> 0 | P21: =O21/$O$3% -> #DIV/0!
B22: ./. Abschreibungen | C22: =Finanz_AfA_Investitionen!F28 -> 0 | D22: =Finanz_AfA_Investitionen!F28 -> 0 | E22: =Finanz_AfA_Investitionen!F28 -> 0 | F22: =Finanz_AfA_Investitionen!F28 -> 0 | G22: =Finanz_AfA_Investitionen!F28 -> 0 | H22: =Finanz_AfA_Investitionen!F28 -> 0 | I22: =Finanz_AfA_Investitionen!F28 -> 0 | J22: =Finanz_AfA_Investitionen!F28 -> 0 | K22: =Finanz_AfA_Investitionen!F28 -> 0 | L22: =Finanz_AfA_Investitionen!F28 -> 0 | M22: =Finanz_AfA_Investitionen!F28 -> 0 | N22: =Finanz_AfA_Investitionen!F28 -> 0 | O22: =SUM(C22:N22) -> 0 | P22: =O22/$O$3% -> #DIV/0!
B23: Gewinn/Verlust | C23: =C21-C22 -> 0 | D23: =D21-D22 -> 0 | E23: =E21-E22 -> 0 | F23: =F21-F22 -> 0 | G23: =G21-G22 -> 0 | H23: =H21-H22 -> 0 | I23: =I21-I22 -> 0 | J23: =J21-J22 -> 0 | ... O23: =O21-O22 -> 0 | P23: =O23/$O$3% -> #DIV/0! | R23: Die Vorlage dieser Datei wurde zur Verfügung gestellt durch die Wirtschafts-Senioren Hannover
B24: Aufgelaufene Werte | C24: ='Ertragsv. 2026'!C23 -> 0 | D24: =C24+D23 -> 0 | E24: =D24+E23 -> 0 | F24: =E24+F23 -> 0 | G24: =F24+G23 -> 0 | H24: =G24+H23 -> 0 | I24: =H24+I23 -> 0 | J24: =I24+J23 -> 0 | K24: =J24+K23 -> 0 | ... N24: =M24+N23 -> 0 | P24: =O24/$O$3% -> #DIV/0!
B25: Kalk. Steuern(ESt/Soli/GeSt) | C25: =IF($K$32=1,C23*$I$32,IF($K$32=2,C23*$I$33)) -> 0 | D25: =IF($K$32=1,D23*$I$32,IF($K$32=2,D23*$I$33)) -> 0 | E25: =IF($K$32=1,E23*$I$32,IF($K$32=2,E23*$I$33)) -> 0 | F25: =IF($K$32=1,F23*$I$32,IF($K$32=2,F23*$I$33)) -> 0 | G25: =IF($K$32=1,G23*$I$32,IF($K$32=2,G23*$I$33)) -> 0 | H25: =IF($K$32=1,H23*$I$32,IF($K$32=2,H23*$I$33)) -> 0 | I25: =IF($K$32=1,I23*$I$32,IF($K$32=2,I23*$I$33)) -> 0 | J25: =IF($K$32=1,J23*$I$32,IF($K$32=2,J23*$I$33)) -> 0 | ... N25: =IF($K$32=1,N23*$I$32,IF($K$32=2,N23*$I$33)) -> 0 | O25: =SUM(C25:N25) -> 0 | P25: =O25/$O$3% -> #DIV/0!
B26: Gewinn/Verlust n.Steuern | C26: =C23-C25 -> 0 | D26: =D23-D25 -> 0 | E26: =E23-E25 -> 0 | F26: =F23-F25 -> 0 | G26: =G23-G25 -> 0 | H26: =H23-H25 -> 0 | I26: =I23-I25 -> 0 | J26: =J23-J25 -> 0 | ... N26: =N23-N25 -> 0 | O26: =SUM(C26:N26) -> 0 | P26: =O26/$O$3% -> #DIV/0!
B27: UnternehmerInnen-Lohn | C27: =M43 -> 0 | D27: =M43 -> 0 | E27: =M43 -> 0 | F27: =M43 -> 0 | G27: =M43 -> 0 | H27: =M43 -> 0 | I27: =M43 -> 0 | J27: =M43 -> 0 | K27: =M43 -> 0 | L27: =M43 -> 0 | M27: =M43 -> 0 | N27: =M43 -> 0 | O27: =SUM(C27:N27) -> 0 | P27: =O27/$O$3% -> #DIV/0!
B28: Darstellung Risikobetrag Umsatzlose Zeit | L28: in % vom Umsatz | O28: =(O20-O4+O22)*Q42 -> 0 | P28: =O28/$O$3% -> #DIV/0!
B29: Darstellung Risikobetrag Saisonverkäufe | L29: in % vom Wareneinkauf | O29: =O4*Q41 -> 0 | P29: =O29/$O$3% -> #DIV/0!
B31: Steuern individuell | C31: je nach Einkommen für den Mindeststundensatz | I31: =C32+E32 -> 0.1477
B32: Steuern Einzelfirma | C32: 0.14 | D32: EST | E32: =C32*5.5% -> 0.0077 | F32: Soli | G32: 0.11 | H32: GeSt | I32: =C32+E32+G32 -> 0.2577 | K32: 1
B33: Steuern GmbH | C33: 0.15 | D33: KöSt | E33: =C33*5.5% -> 0.00825 | F33: Soli | G33: 0.14 | H33: GeSt | I33: =C33+E33+G33 -> 0.29825
B35: GESAMTKALKULATION | C35: 1) PRIVATE KOSTEN + 2) GEWERBLICHE KOSTEN + WARENEINSATZ + 3) 3% RISIKOZUSCHLAG UNTERNEHM. TÄTIGKEIT (SOZIALE SICHERUNG) + 4) 10% EIGENKAPITALVERZINSUNG + 5) KALKULATORISCHE STEUERN + 6) 5% REINGEWINNANSPRUCH ) +7) 2% GARANTIE / GEWÄHRLEISTUNG/ SCHWUND UND VORSORGE FÜR FORDERUNGSVERLUSTE , +8) RISIKOZUSCHLAG FÜR SAISON-/SONDERVERKÄUFE / NACHLÄSSE +9) RISIKOZUSCHLAG FÜR UNTERAUSLASTUNG UND UMSATZLOSE ZEIT
C36: 1) | D36: + 2) | E36: + 3) | F36: + 4) | G36: + 5) | H36: + 6) | I36: + 7) | J36: +8) | K36: +9) | M36: Mindestumsatz
B37: Mindestumsatz | C37: =Privatentnahmen!F35 -> 0 | D37: =(O20+O22)/12 -> 0 | E37: =(O3/12)*Q37 -> 0 | F37: =Finanz_AfA_Investitionen!C31*Q38/12 -> 0 | G37: =O25/12 -> 0 | H37: =O3/12*Q39 -> 0 | I37: =O3/12*Q40 -> 0 | J37: =O29/12 -> 0 | K37: =IF(O4>1,(O28/12),IF(O4<1,0)) -> 0 | M37: =SUM(C37:K37) -> 0 | P37: 3) | Q37: 0.01
C38: 1) | D38: + 2a) | E38: + 3) | F38: + 4) | G38: + 5) | H38: + 6) | I38: +7) | J38: +8) | K38: +9) | L38: =IF(ArbStd_MA!$G$33>=1,ArbStd_MA!$G$33,IF(ArbStd_MA!$G$33<=1,ArbStd_MA!$F$23)) -> 144 | M38: Stundensatz | P38: 4) | Q38: 0.2
B39: Mindeststundensatz | C39: =Privatentnahmen!F35 -> 0 | D39: =(O20-O4+O22)/12 -> 0 | G39: =C39*I31 -> 0 | L39: =IF(ArbStd_MA!$G$33>=1,ArbStd_MA!$G$33,IF(ArbStd_MA!$G$33<=1,ArbStd_MA!$F$23)) -> 144 | M39: =(C39+D39+G39+K39)/L39/ArbStd_MA!G49 -> 0 | P39: 6) | Q39: 0.05
B40: Stundenverkaufssatz | C40: =Privatentnahmen!F35 -> 0 | D40: =D39 -> 0 | E40: =(O3/12)*Q37 -> 0 | F40: =F37 -> 0 | G40: =O25/12 -> 0 | H40: =O3/12*Q39 -> 0 | I40: =I37 -> 0 | L40: =IF(ArbStd_MA!$G$33>=1,ArbStd_MA!$G$33,IF(ArbStd_MA!$G$33<=1,ArbStd_MA!$F$23)) -> 144 | M40: =(C40+D40+E40+F40+G40+H40+I40+J40+K40)/L40/ArbStd_MA!G49 -> 0 | P40: 7) | Q40: 0.02
B41: relative Stundensatzdifferenz | M41: =ROUND((M40-M39)/M39*100,1)& " %" -> #DIV/0! | P41: 8) | Q41: 0.1
B42: Rohaufschlag im Handel % | C42: =C40 -> 0 | D42: =D40 -> 0 | E42: =E40 -> 0 | F42: =F40 -> 0 | G42: =G40 -> 0 | H42: =H40 -> 0 | I42: =I40 -> 0 | J42: =J37 -> 0 | K42: =K37 -> 0 | M42: =IF(O4<1,0,(C42+D42+E42+F42+G42+H42+I42+J42+K42)*100*12/O4) -> 0 | P42: 9) | Q42: 0.1
...

Sheet Ertragsv. 2027
B1: ERTRAGSVORSCHAU 3. Planjahr | E1: =ZusammenführErgebn!E3 -> 2027 | H1: =Deckblatt!C5 -> Max Mustermann
A2: Durchschn. Warenein-satz | B2: ALLE ANGABEN NETTO | C2: ='Ertragsv. 2025'!C2 -> Jan. | D2: ='Ertragsv. 2025'!D2 -> Febr. | E2: ='Ertragsv. 2025'!E2 -> März | F2: ='Ertragsv. 2025'!F2 -> April | G2: ='Ertragsv. 2025'!G2 -> Mai | H2: ='Ertragsv. 2025'!H2 -> Juni | I2: ='Ertragsv. 2025'!I2 -> Juli | J2: ='Ertragsv. 2025'!J2 -> Aug. | ... N2: ='Ertragsv. 2025'!N2 -> Dez. | O2: SUMME | P2: % | Q2: Branchen-vergl. | R2: ERLÄUTERUNGEN / KOMMENTARE
B3: Umsatz/ Erlöse | C3: ='UmstzPlan 1.-3.Jahr'!E57 -> 0 | D3: ='UmstzPlan 1.-3.Jahr'!G57 -> 0 | E3: ='UmstzPlan 1.-3.Jahr'!I57 -> 0 | F3: ='UmstzPlan 1.-3.Jahr'!K57 -> 0 | G3: ='UmstzPlan 1.-3.Jahr'!M57 -> 0 | H3: ='UmstzPlan 1.-3.Jahr'!O57 -> 0 | I3: ='UmstzPlan 1.-3.Jahr'!Q57 -> 0 | J3: ='UmstzPlan 1.-3.Jahr'!S57 -> 0 | K3: ='UmstzPlan 1.-3.Jahr'!U57 -> 0 | L3: ='UmstzPlan 1.-3.Jahr'!W57 -> 0 | M3: ='UmstzPlan 1.-3.Jahr'!Y57 -> 0 | N3: ='UmstzPlan 1.-3.Jahr'!AA57 -> 0 | O3: =SUM(C3:N3) -> 0 | P3: 100
A4: 0.12 | B4: ./.Materialeinsatz | C4: =C3*$A$4 -> 0 | D4: =D3*$A$4 -> 0 | E4: =E3*$A$4 -> 0 | F4: =F3*$A$4 -> 0 | G4: =G3*$A$4 -> 0 | H4: =H3*$A$4 -> 0 | I4: =I3*$A$4 -> 0 | J4: =J3*$A$4 -> 0 | ... N4: =N3*$A$4 -> 0 | O4: =SUM(C4:N4) -> 0 | P4: =O4/$O$3% -> #DIV/0!
B5: ./. Kosten:
B6: Raumkosten | C6: 0 | D6: 0 | E6: 0 | F6: 0 | G6: 0 | H6: 0 | I6: 0 | J6: 0 | K6: 0 | L6: 0 | M6: 0 | N6: 0 | O6: =SUM(C6:N6) -> 0 | P6: =O6/$O$3% -> #DIV/0! | R6: Beispiel: Büromiete 12% der Wohnung
B7: Kfz Steuer | C7: 0 | D7: 0 | E7: 0 | F7: 0 | G7: 0 | H7: 0 | I7: 0 | J7: 0 | K7: 0 | L7: 0 | M7: 0 | N7: 0 | O7: =SUM(C7:N7) -> 0 | P7: =O7/$O$3% -> #DIV/0! | R7: anteilig gem.Nutzung
B8: Kraftfahrzeugkosten | C8: 0 | D8: 0 | E8: 0 | F8: 0 | G8: 0 | H8: 0 | I8: 0 | J8: 0 | K8: 0 | L8: 0 | M8: 0 | N8: 0 | O8: =SUM(C8:N8) -> 0 | P8: =O8/$O$3% -> #DIV/0! | R8: gem.geschätz.mtl Kilometerleistung
B9: Leasing | C9: =Finanz_AfA_Investitionen!$H28 -> 0 | D9: =Finanz_AfA_Investitionen!$H28 -> 0 | E9: =Finanz_AfA_Investitionen!$H28 -> 0 | F9: =Finanz_AfA_Investitionen!$H28 -> 0 | G9: =Finanz_AfA_Investitionen!$H28 -> 0 | H9: =Finanz_AfA_Investitionen!$H28 -> 0 | I9: =Finanz_AfA_Investitionen!$H28 -> 0 | J9: =Finanz_AfA_Investitionen!$H28 -> 0 | ... N9: =Finanz_AfA_Investitionen!$H28 -> 0 | O9: =SUM(C9:N9) -> 0 | P9: =O9/$O$3% -> #DIV/0!
B10: Werbe- und Reisekosten | O10: =SUM(C10:N10) -> 0 | P10: =O10/$O$3% -> #DIV/0!
B11: Telefon, Telefax, Internet | O11: =SUM(C11:N11) -> 0 | P11: =O11/$O$3% -> #DIV/0!
B12: Bürobedarf | O12: =SUM(C12:N12) -> 0 | P12: =O12/$O$3% -> #DIV/0!
B13: Rechts- und Beratungskosten | O13: =SUM(C13:N13) -> 0 | P13: =O13/$O$3% -> #DIV/0! | R13: Beitrag Berufsverb.
B14: Versicherungen/Beiträge | O14: =SUM(C14:N14) -> 0 | P14: =O14/$O$3% -> #DIV/0!
B15: Reparaturen/Instandhaltung | O15: =SUM(C15:N15) -> 0 | P15: =O15/$O$3% -> #DIV/0!
B16: sonstiger Betriebsaufwand | O16: =SUM(C16:N16) -> 0 | P16: =O16/$O$3% -> #DIV/0!
B17: Zinsaufwand | C17: =Finanz_AfA_Investitionen!$I$38-Finanz_AfA_Investitionen!I37+'Mikrostarter Geschäftsplan'!D46 -> 0 | D17: =Finanz_AfA_Investitionen!$I$38-Finanz_AfA_Investitionen!I37+'Mikrostarter Geschäftsplan'!D47 -> 0 | E17: =Finanz_AfA_Investitionen!$I$38-Finanz_AfA_Investitionen!I37+'Mikrostarter Geschäftsplan'!D48 -> 0 | F17: =Finanz_AfA_Investitionen!$I$38-Finanz_AfA_Investitionen!I37+'Mikrostarter Geschäftsplan'!D49 -> 0 | G17: =Finanz_AfA_Investitionen!$I$38-Finanz_AfA_Investitionen!I37+'Mikrostarter Geschäftsplan'!D50 -> 0 | H17: =Finanz_AfA_Investitionen!$I$38-Finanz_AfA_Investitionen!I37+'Mikrostarter Geschäftsplan'!D51 -> 0 | I17: =Finanz_AfA_Investitionen!$I$38-Finanz_AfA_Investitionen!I37+'Mikrostarter Geschäftsplan'!D52 -> 0 | J17: =Finanz_AfA_Investitionen!$I$38-Finanz_AfA_Investitionen!I37+'Mikrostarter Geschäftsplan'!D53 -> 0 | K17: =Finanz_AfA_Investitionen!$I$38-Finanz_AfA_Investitionen!I37+'Mikrostarter Geschäftsplan'!D54 -> 0 | L17: =Finanz_AfA_Investitionen!$I$38-Finanz_AfA_Investitionen!I37+'Mikrostarter Geschäftsplan'!D55 -> 0 | M17: =Finanz_AfA_Investitionen!$I$38-Finanz_AfA_Investitionen!I37+'Mikrostarter Geschäftsplan'!D56 -> 0 | N17: =Finanz_AfA_Investitionen!$I$38-Finanz_AfA_Investitionen!I37+'Mikrostarter Geschäftsplan'!D57 -> 0 | O17: =SUM(C17:N17) -> 0 | P17: =O17/$O$3% -> #DIV/0!
B18: PersonalkostenAGA | C18: =ArbStd_MA!$I$112+ArbStd_MA!$I$117 -> 0 | D18: =ArbStd_MA!$I$112+ArbStd_MA!$I$117 -> 0 | E18: =ArbStd_MA!$I$112+ArbStd_MA!$I$117 -> 0 | F18: =ArbStd_MA!$I$112+ArbStd_MA!$I$117 -> 0 | G18: =ArbStd_MA!$I$112+ArbStd_MA!$I$117 -> 0 | H18: =ArbStd_MA!$I$112+ArbStd_MA!$I$117 -> 0 | I18: =ArbStd_MA!$I$112+ArbStd_MA!$I$117 -> 0 | J18: =ArbStd_MA!$I$112+ArbStd_MA!$I$117 -> 0 | ... N18: =ArbStd_MA!$I$112+ArbStd_MA!$I$117 -> 0 | O18: =SUM(C18:N18) -> 0 | P18: =O18/$O$3% -> #DIV/0!
P19: =O19/$O$3% -> #DIV/0!
B20: Summe Aufwendungen | C20: =SUM(C4:C19) -> 0 | D20: =SUM(D4:D19) -> 0 | E20: =SUM(E4:E19) -> 0 | F20: =SUM(F4:F19) -> 0 | G20: =SUM(G4:G19) -> 0 | H20: =SUM(H4:H19) -> 0 | I20: =SUM(I4:I19) -> 0 | J20: =SUM(J4:J19) -> 0 | ... N20: =SUM(N4:N19) -> 0 | O20: =SUM(C20:N20) -> 0 | P20: =O20/$O$3% -> #DIV/0!
B21: Betriebsergebnis | C21: =C3-C20 -> 0 | D21: =D3-D20 -> 0 | E21: =E3-E20 -> 0 | F21: =F3-F20 -> 0 | G21: =G3-G20 -> 0 | H21: =H3-H20 -> 0 | I21: =I3-I20 -> 0 | J21: =J3-J20 -> 0 | ... N21: =N3-N20 -> 0 | O21: =SUM(C21:N21) -> 0 | P21: =O21/$O$3% -> #DIV/0!
B22: ./. Abschreibungen | C22: =Finanz_AfA_Investitionen!F28 -> 0 | D22: =Finanz_AfA_Investitionen!F28 -> 0 | E22: =Finanz_AfA_Investitionen!F28 -> 0 | F22: =Finanz_AfA_Investitionen!F28 -> 0 | G22: =Finanz_AfA_Investitionen!F28 -> 0 | H22: =Finanz_AfA_Investitionen!F28 -> 0 | I22: =Finanz_AfA_Investitionen!F28 -> 0 | J22: =Finanz_AfA_Investitionen!F28 -> 0 | K22: =Finanz_AfA_Investitionen!F28 -> 0 | L22: =Finanz_AfA_Investitionen!F28 -> 0 | M22: =Finanz_AfA_Investitionen!F28 -> 0 | N22: =Finanz_AfA_Investitionen!F28 -> 0 | O22: =SUM(C22:N22) -> 0 | P22: =O22/$O$3% -> #DIV/0!
B23: Gewinn/Verlust | C23: =C21-C22 -> 0 | D23: =D21-D22 -> 0 | E23: =E21-E22 -> 0 | F23: =F21-F22 -> 0 | G23: =G21-G22 -> 0 | H23: =H21-H22 -> 0 | I23: =I21-I22 -> 0 | J23: =J21-J22 -> 0 | ... O23: =O21-O22 -> 0 | P23: =O23/$O$3% -> #DIV/0!
B24: Aufgelaufene Werte | C24: ='Ertragsv. 2027'!C23 -> 0 | D24: =C24+D23 -> 0 | E24: =D24+E23 -> 0 | F24: =E24+F23 -> 0 | G24: =F24+G23 -> 0 | H24: =G24+H23 -> 0 | I24: =H24+I23 -> 0 | J24: =I24+J23 -> 0 | K24: =J24+K23 -> 0 | ... N24: =M24+N23 -> 0 | P24: =O24/$O$3% -> #DIV/0!
B25: Kalk. Steuern(ESt/Soli/GeSt) | C25: =IF($K$32=1,C23*$I$32,IF($K$32=2,C23*$I$33)) -> 0 | D25: =IF($K$32=1,D23*$I$32,IF($K$32=2,D23*$I$33)) -> 0 | E25: =IF($K$32=1,E23*$I$32,IF($K$32=2,E23*$I$33)) -> 0 | F25: =IF($K$32=1,F23*$I$32,IF($K$32=2,F23*$I$33)) -> 0 | G25: =IF($K$32=1,G23*$I$32,IF($K$32=2,G23*$I$33)) -> 0 | H25: =IF($K$32=1,H23*$I$32,IF($K$32=2,H23*$I$33)) -> 0 | I25: =IF($K$32=1,I23*$I$32,IF($K$32=2,I23*$I$33)) -> 0 | J25: =IF($K$32=1,J23*$I$32,IF($K$32=2,J23*$I$33)) -> 0 | ... N25: =IF($K$32=1,N23*$I$32,IF($K$32=2,N23*$I$33)) -> 0 | O25: =SUM(C25:N25) -> 0 | P25: =O25/$O$3% -> #DIV/0!
B26: Gewinn/Verlust n.Steuern | C26: =C23-C25 -> 0 | D26: =D23-D25 -> 0 | E26: =E23-E25 -> 0 | F26: =F23-F25 -> 0 | G26: =G23-G25 -> 0 | H26: =H23-H25 -> 0 | I26: =I23-I25 -> 0 | J26: =J23-J25 -> 0 | ... N26: =N23-N25 -> 0 | O26: =SUM(C26:N26) -> 0 | P26: =O26/$O$3% -> #DIV/0!
B27: UnternehmerInnen-Lohn | C27: =M43 -> 0 | D27: =M43 -> 0 | E27: =M43 -> 0 | F27: =M43 -> 0 | G27: =M43 -> 0 | H27: =M43 -> 0 | I27: =M43 -> 0 | J27: =M43 -> 0 | K27: =M43 -> 0 | L27: =M43 -> 0 | M27: =M43 -> 0 | N27: =M43 -> 0 | O27: =SUM(C27:N27) -> 0 | P27: =O27/$O$3% -> #DIV/0!
B28: Darstellung Risikobetrag Umsatzlose Zeit | L28: in % vom Umsatz | O28: =(O20-O4+O22)*Q42 -> 0 | P28: =O28/$O$3% -> #DIV/0!
B29: Darstellung Risikobetrag Saisonverkäufe | L29: in % vom Wareneinkauf | O29: =O4*Q41 -> 0 | P29: =O29/$O$3% -> #DIV/0!
B31: Steuern individuell | C31: je nach Einkommen für den Mindeststundensatz | I31: =C32+E32 -> 0.1477
B32: Steuern Einzelfirma | C32: 0.14 | D32: EST | E32: =C32*5.5% -> 0.0077 | F32: Soli | G32: 0.1 | H32: GeSt | I32: =C32+E32+G32 -> 0.2477 | K32: 1
B33: Steuern GmbH | C33: 0.15 | D33: KöSt | E33: =C33*5.5% -> 0.00825 | F33: Soli | G33: 0.14 | H33: GeSt | I33: =C33+E33+G33 -> 0.29825
B35: GESAMTKALKULATION | C35: 1) PRIVATE KOSTEN + 2) GEWERBLICHE KOSTEN + WARENEINSATZ + 3) 3% RISIKOZUSCHLAG UNTERNEHM. TÄTIGKEIT (SOZIALE SICHERUNG) + 4) 10% EIGENKAPITALVERZINSUNG + 5) KALKULATORISCHE STEUERN + 6) 5% REINGEWINNANSPRUCH ) +7) 2% GARANTIE/ GEWÄHRLEISTUNG/SCHWUND UND VORSORGE FÜR FORDERUNGSVERLUSTE, +8) RISIKOZUSCHLAG FÜR SAISON-/SONDERVERKÄUFE / NACHLÄSSE +9) RISIKOZUSCHLAG FÜR UNTERAUSLASTUNG UND UMSATZLOSE ZEIT
C36: 1) | D36: + 2) | E36: + 3) | F36: + 4) | G36: + 5) | H36: + 6) | I36: + 7) | J36: +8) | K36: +9) | M36: Mindestumsatz
B37: Mindestumsatz | C37: =Privatentnahmen!H35 -> 0 | D37: =(O20+O22)/12 -> 0 | E37: =(O3/12)*Q37 -> 0 | F37: =Finanz_AfA_Investitionen!C31*Q38/12 -> 0 | G37: =O25/12 -> 0 | H37: =O3/12*Q39 -> 0 | I37: =O3/12*Q40 -> 0 | J37: =O29/12 -> 0 | K37: =IF(O4>1,(O28/12),IF(O4<1,0)) -> 0 | M37: =SUM(C37:K37) -> 0 | P37: 3) | Q37: 0.03
C38: 1) | D38: + 2a) | E38: + 3) | F38: + 4) | G38: + 5) | H38: + 6) | I38: +7) | J38: +8) | K38: +9) | L38: =IF(ArbStd_MA!$I$33>=1,ArbStd_MA!$I$33,IF(ArbStd_MA!$I$33<=1,ArbStd_MA!$H$23)) -> 144 | M38: Stundensatz | P38: 4) | Q38: 0.1
B39: Mindeststundensatz | C39: =Privatentnahmen!H35 -> 0 | D39: =(O20-O4+O22)/12 -> 0 | G39: =C39*I31 -> 0 | L39: =IF(ArbStd_MA!$I$33>=1,ArbStd_MA!$I$33,IF(ArbStd_MA!$I$33<=1,ArbStd_MA!$H$23)) -> 144 | M39: =(C39+D39+G39+K39)/L39/ArbStd_MA!H49 -> 0 | P39: 6) | Q39: 0.05
B40: Stundenverkaufssatz | C40: =Privatentnahmen!H35 -> 0 | D40: =D39 -> 0 | E40: =(O3/12)*Q37 -> 0 | F40: =F37 -> 0 | G40: =O25/12 -> 0 | H40: =O3/12*Q39 -> 0 | I40: =I37 -> 0 | L40: =IF(ArbStd_MA!$I$33>=1,ArbStd_MA!$I$33,IF(ArbStd_MA!$I$33<=1,ArbStd_MA!$H$23)) -> 144 | M40: =(C40+D40+E40+F40+G40+H40+I40+J40+K40)/L40/ArbStd_MA!H49 -> 0 | P40: 7) | Q40: 0.02
B41: relative Stundensatzdifferenz | M41: =ROUND((M40-M39)/M39*100,1)& " %" -> #DIV/0! | P41: 8) | Q41: 0.1
B42: Rohaufschlag im Handel % | C42: =C40 -> 0 | D42: =D40 -> 0 | E42: =E40 -> 0 | F42: =F40 -> 0 | G42: =G40 -> 0 | H42: =H40 -> 0 | I42: =I40 -> 0 | J42: =J37 -> 0 | K42: =K37 -> 0 | M42: =IF(O4<1,0,(C42+D42+E42+F42+G42+H42+I42+J42+K42)*100*12/O4) -> 0 | P42: 9) | Q42: 0.1
...

Sheet UmstzPlan 1.-3.Jahr
B1: Bei länger laufenden Aufträgen (mehr als ein Monat) können die Stunden oder die Umsätze aufgeteilt werden, oder das Produkt gestückelt werden!
B2: UMSATZPLANUNG
B3: 1. GESCHÄFTSJAHR | C3: =ZusammenführErgebn!C3 -> 2025 | E3: ='Ertragsv. 2025'!C2 -> Jan. | G3: ='Ertragsv. 2025'!D2 -> Febr. | I3: ='Ertragsv. 2025'!E2 -> März | K3: ='Ertragsv. 2025'!F2 -> April | M3: ='Ertragsv. 2025'!G2 -> Mai | O3: ='Ertragsv. 2025'!H2 -> Juni | Q3: ='Ertragsv. 2025'!I2 -> Juli | S3: ='Ertragsv. 2025'!J2 -> Aug. | U3: ='Ertragsv. 2025'!K2 -> Sept. | W3: ='Ertragsv. 2025'!L2 -> Okt. | Y3: ='Ertragsv. 2025'!M2 -> Nov. | AA3: ='Ertragsv. 2025'!N2 -> Dez. | AC3: SUMME PRODUKTE / DL | AD3: SUMME DER EINZEL- UMSÄTZE | AE3: UMSATZ- STRUKTUR IN % | AG3: STRUKTUR DER EINKAUFSPREISE (Handel+Gastronomie)
B5: Prod.Std./Monat_Soll | F5: =IF(ArbStd_MA!$D$33>=1,ArbStd_MA!$D$33,IF(ArbStd_MA!$D$33<1,ArbStd_MA!$D$23)) -> 144 | H5: =IF(ArbStd_MA!$D$33>=1,ArbStd_MA!$D$33,IF(ArbStd_MA!$D$33<1,ArbStd_MA!$D$23)) -> 144 | J5: =IF(ArbStd_MA!$D$33>=1,ArbStd_MA!$D$33,IF(ArbStd_MA!$D$33<1,ArbStd_MA!$D$23)) -> 144 | L5: =IF(ArbStd_MA!$D$33>=1,ArbStd_MA!$D$33,IF(ArbStd_MA!$D$33<1,ArbStd_MA!$D$23)) -> 144 | N5: =IF(ArbStd_MA!$D$33>=1,ArbStd_MA!$D$33,IF(ArbStd_MA!$D$33<1,ArbStd_MA!$D$23)) -> 144 | P5: =IF(ArbStd_MA!$D$33>=1,ArbStd_MA!$D$33,IF(ArbStd_MA!$D$33<1,ArbStd_MA!$D$23)) -> 144 | R5: =IF(ArbStd_MA!$D$33>=1,ArbStd_MA!$D$33,IF(ArbStd_MA!$D$33<1,ArbStd_MA!$D$23)) -> 144 | T5: =IF(ArbStd_MA!$D$33>=1,ArbStd_MA!$D$33,IF(ArbStd_MA!$D$33<1,ArbStd_MA!$D$23)) -> 144 | V5: =IF(ArbStd_MA!$D$33>=1,ArbStd_MA!$D$33,IF(ArbStd_MA!$D$33<1,ArbStd_MA!$D$23)) -> 144 | X5: =IF(ArbStd_MA!$D$33>=1,ArbStd_MA!$D$33,IF(ArbStd_MA!$D$33<1,ArbStd_MA!$D$23)) -> 144 | Z5: =IF(ArbStd_MA!$D$33>=1,ArbStd_MA!$D$33,IF(ArbStd_MA!$D$33<1,ArbStd_MA!$D$23)) -> 144 | AB5: =IF(ArbStd_MA!$D$33>=1,ArbStd_MA!$D$33,IF(ArbStd_MA!$D$33<1,ArbStd_MA!$D$23)) -> 144
B6: LeistungStd. Ist | F6: =SUM(F9:F18) -> 0 | H6: =SUM(H9:H18) -> 0 | J6: =SUM(J9:J18) -> 0 | L6: =SUM(L9:L18) -> 0 | N6: =SUM(N9:N18) -> 0 | P6: =SUM(P9:P18) -> 0 | R6: =SUM(R9:R18) -> 0 | T6: =SUM(T9:T18) -> 0 | V6: =SUM(V9:V18) -> 0 | X6: =SUM(X9:X18) -> 0 | Z6: =SUM(Z9:Z18) -> 0 | AB6: =SUM(AB9:AB18) -> 0 | AC6: =SUM(E6:AB6)/12 -> 0
C7: Einzel- preis | D7: Prod. Stunden | E7: verk. Stück | F7: Prod.Std. gesamt | G7: verk. Stück | H7: Prod.Std. gesamt | I7: verk. Stück | J7: Prod.Std. gesamt | K7: verk. Stück | L7: Prod.Std. gesamt | M7: verk. Stück | N7: Prod.Std. gesamt | O7: verk. Stück | P7: Prod.Std. gesamt | Q7: verk. Stück | R7: Prod.Std. gesamt | S7: verk. Stück | T7: Prod.Std. gesamt | U7: verk. Stück | V7: Prod.Std. gesamt | W7: verk. Stück | X7: Prod.Std. gesamt | Y7: verk. Stück | Z7: Prod.Std. gesamt | AA7: verk. Stück | AB7: Prod.Std. gesamt | AG7: Einzelpreis | AH7: EK Gesamt
B9: Webseite Teil I | F9: =D9*E9 -> 0 | H9: =D9*G9 -> 0 | J9: =D9*I9 -> 0 | L9: =D9*K9 -> 0 | N9: =D9*M9 -> 0 | P9: =D9*O9 -> 0 | R9: =D9*Q9 -> 0 | T9: =D9*S9 -> 0 | V9: =D9*U9 -> 0 | X9: =D9*W9 -> 0 | Z9: =D9*Y9 -> 0 | AB9: =D9*AA9 -> 0 | AC9: =E9+G9+I9+K9+M9+O9+Q9+S9+U9+W9+Y9+AA9 -> 0 | AD9: =(E9+G9+I9+K9+M9+O9+Q9+S9+U9+W9+Y9+AA9)*C9 -> 0 | AE9: =AD9/$AD$19 -> #DIV/0! | AG9: 300 | AH9: =AC9*AG9 -> 0
